# Java throw

> 原文:[https://www.tutorialandexample.com/java-throw/](https://www.tutorialandexample.com/java-throw/)

**Java 抛出**

有时在代码中需要故意抛出一个异常。为了达到同样的效果，应该使用 **Java throw** 关键字。使用 throw 关键字可以抛出未检查的或检查的异常。然而， *throw* 关键字主要用于在 *throws* 关键字的帮助下生成自定义异常。

**语法:**

```
throw exception;
```

**例如:**

```
throw new IOException(“The device is not found.”);
```

**Java 抛出关键字**

让我们借助一些例子来试着理解一下关键字 throw 的用法。

**抛出未检查的异常**

**文件名**:ThrowExample.java

```
 public class ThrowExample
 {
   // A method that throws an exception   
   public void divideByZero()
   {
     // throwing the exception intentionally  
     throw new ArithmeticException("0 is used as a divisor in the division process.");
   }
   // main method
   public static void main(String argvs[])
   {
      // creating an object of the ThrowExample class 
     ThrowExample obj = new ThrowExample();
     try
     {
         // invoking the method divideByZero
         obj.divideByZero();
     }
     // handling the exception
     catch(Exception te)
     {
         System.out.println(te);
     }
   }
 } 
```

**输出:**

```
java.lang.ArithmeticException: 0 is used as a divisor in the division process.
```

**解释:**try-catch 块处理在 *divideByZero()* 方法中显式引发的异常。注意*算术异常*是未检查异常的一个例子。

**抛出已检查的异常**

**文件名**:ThrowExample1.java

```
 // importing the exception IOException
 import java.io.IOException;
 public class ThrowExample1
 {
 // main method
 public static void main(String argvs[])
 {
 // handling the exception
 try
 {
   throw new IOException("Unable to find the file.");
 }
 catch (IOException IOExObj)
 {
   System.out.println(IOExObj.getMessage());
 }
 System.out.println("Remaining code that follows the try - catch block.");
 }
 } 
```

**输出:**

```
Unable to find the file.
Remaining code that follows the try - catch block.
```

**解释:**现在， *throw* 关键字生成一个检查过的异常，该异常正在 try-catch 块中处理。注意， *IOException* 是一个被检查的异常。

**抛出自定义异常**

Java throw 关键字也可以用来抛出一个定制的异常。自定义异常在 Java 项目中扮演着非常重要的角色。可以看出，大多数时候，自定义异常比内置异常使用得更频繁。自定义异常非常方便地显示特定于项目的消息。下面说明了如何引发自定义异常。

**文件名**:ThrowExample2.java

```
 class InvalidNumberException extends Exception
 { 
 // constructor of the class
 InvalidNumberException(String str)
 {
 // invoking the constructor of the parent class
 super(str); 
 }
 } 
 public class ThrowExample2
 { 
 // main method
 public static void main(String argvs[])
 {
   try
   { 
     // custome exception is raised
     throw new InvalidNumberException("25 is not valid number. Number should be less than 20.");
   }
   // handling the raised custom exception
   catch(Exception e)
   {
       System.out.println("An exception occurred: "+ e);
   } 
   System.out.println("Code following the try catch block."); 
 } 
 }  
```

**输出:**

```
 An exception occurreda: InvalidNumberException: 25 is not valid number. Number should be less than 20.
 Code following the try catch block. 
```

**说明:**异常类必须作为父类使用，才能创建我们自己的异常。为了显示所需的消息，必须调用父类的构造函数，即*异常*类。*超级(str)；*语句也是如此。代码的其余部分很容易理解。