# Java 终于

> 原文：<https://www.tutorialandexample.com/java-finally/>

**Java finally** :程序中有一些语句的执行极其重要。例如，关闭数据库连接。关闭数据库连接的语句必须放在**Java*finally*T5】块中。Java finally 块确保 finally 块中出现的任何语句都必须被执行，而不管程序中是否出现异常。Java 最终可以与 try-catch 一起使用，或者只能与 try 关键字一起使用。**

**Java finally 语法**

下面提到了 *finally* 关键字的语法。

```
 try
 {
     // Statements that are potent to cause an exception
 }
 catch
 {
    // for Handling the raised exception
 }
 finally
 {
    // Statements that have to be executed irrespective of an exception raised or not
 }
 We can also use finally without using catch.
 try
 {
     // Statements that are potent to cause an exception
 }
 finally
 {
    // Statements that have to be executed irrespective of an exception raised or not
 } 
```

### Java finally 关键字示例

最后让我们借助一些例子来试着理解一下关键字的用法。

**文件名**:FinallyExample.java

```
 public class FinallyExample
 {
 // main method
 public static void main(String argvs[])
 {
 try
 {
 // an int array of 9 elements
 int arr[] = new int[9];
 arr[10] = 90; // raises ArrayIndexOutOfBoundsException
 System.out.println(arr);  // this statement never gets executed
 } 
 catch(ArrayIndexOutOfBoundsException e)
 {
 System.out.println("The used index is out of range." + e);
 } 
 finally
 {
 System.out.println("This print statement has to be executed.");
 } 
 System.out.println("Finally, out of the try - catch - finally block"); 
 }  
 } 
```

**输出:**

```
 The used index is out of range.java.lang.ArrayIndexOutOfBoundsException: Index 10 out of bounds for length 9
 This print statement has to be executed.
 Finally, out of the try - catch – finally block 
```

**解释:**try-catch 块处理*ArrayIndexOutOfBoundsException*。在 try-catch 块之后，控制转移到*最后的*块。现在观察下面的例子。

**文件名**:FinallyExample1.java

```
 public class FinallyExample1
 {
 // main method
 public static void main(String argvs[])
 {
 try
 {
 int x = 7 / 0; // raises ArithmeticException
 System.out.println(x);  // this statement never gets executed
 } 
 finally
 {
 System.out.println("This print statement has to be executed.");
 } 
     // the last print statements
 System.out.println("Finally, out of the try - finally block"); 
 }  
 } 
```

**输出:**

```
 This print statement has to be executed.
 Exception in thread "main" java.lang.ArithmeticException: / by zero
                at FinallyExample1.main(FinallyExample1.java:9) 
```

**解释:**在这个程序中，我们看到*算法异常*在 try 块中被引发。即使引发的异常没有被程序处理，最终*块还是会执行。由此可见*最后*块的重要性。任何必须执行的敏感代码都只能放在 *finally* 块中。请注意，最后一条 print 语句没有执行。这是因为引发的异常没有得到处理，导致程序异常终止。*

### 不执行 Finally 块

即使 finally block 确保了无论发生什么情况都必须执行某些语句。然而，在某些情况下，甚至 *finally* 块也不执行。下面的程序说明了同样的情况。

**文件名**:FinallyExample2.java

```
 public class FinallyExample2
 {
 // main method
 public static void main(String argvs[])
 {
 try
 {
 System.out.println("Inside the Java try block.");
 System.exit(0); // nothing executes after the execution of this statement
 }
 catch (Exception e)
 {
 System.out.println("Inside the Java catch block" + e);
 }
 finally
 {
 System.out.println("Inside the Java finally block");
 }
 System.out.println("Finally, out of the try - catch - finally block");
 }  
 } 
```

**输出:**

```
Inside the Java try block.
```

**说明:**在这个程序中，我们观察到*最后的*块没有被执行。因为声明*system . exit(0)；。**system . exit(0)；*语句通过强制终止 JVM (Java 虚拟机)来停止程序。因此， *finally* 块不执行。

**记住:**

1)最后的*块不能独立存在。它必须带有 try 块或 try-catch 块。*

2)*finally*块总是在 try 块之后执行。

3)catch 块的存在并不能保证*最终*块是否在 catch 块之后执行。下面的程序说明了同样的情况。

**文件名**:FinallyExample3.java

**输出:**

```
 Inside the Java try block.
 Inside the Java finally block.
 Exception in thread "main" java.lang.ArrayIndexOutOfBoundsException: Index 3 out of bounds for length 3
                at FinallyExample3.main(FinallyExample3.java:16) 
```

**解释:**在这个程序中，我们看到 finally 块被执行，catch 块没有被执行。其背后的原因是程序中引发的异常的类型。catch 块期望在 try 块中引发*算术异常*。然而，try 块引发了*ArrayIndexOutOfBoundsException*。因此，期望和现实之间存在不匹配。由于引发的异常没有被处理，最后的打印语句也没有被执行，程序异常终止。在这个例子中，我们看到在 try 块之后，finally 块被执行，即使 catch 块存在。现在，观察下面的程序。

**文件名**:FinallyExample4.java

```
 public class FinallyExample4
 {
 // main method
 public static void main(String argvs[])
 {
 // try - catch - finally    
 try
 {
 System.out.println("Inside the Java try block.");
    // creating an array of three elements
    int arr[] = new int[3];
 arr[3] = 5; // raises ArrayIndexOutOfBoundsException
 }
 catch (ArrayIndexOutOfBoundsException ae)
 {
 System.out.println("Inside the Java catch block \n " + ae);
 }
 finally
 {
 System.out.println("Inside the Java finally block.");
 }
 // the last print statement
 System.out.println("Finally, out of the try - catch - finally block.");
 }  
 } 
```

**输出:**

```
 Inside the Java try block.
 Inside the Java catch block
 java.lang.ArrayIndexOutOfBoundsException: Index 3 out of bounds for length 3
 Inside the Java finally block.
 Finally, out of the try - catch - finally block. 
```

**解释:**在这个程序中，我们看到*最后*块是在 catch 块之后执行的。这是因为引发的异常在 catch 块中得到处理。

4)*finally*块不保证异常不会在其块中引发。

5)如果 *finally* 块内出现的异常没有被处理，程序异常终止。

6)可以在 *finally* 块中使用 try-catch 来处理 *finally* 块中引发的异常。请遵守以下程序。

**文件名**:FinallyExample5.java

```
 public class FinallyExample5
 {
 // main method
 public static void main(String argvs[])
 {
 // try - catch - finally    
 try
 {
 System.out.println("Inside the Java try block.");
    String str = null;
 str.equals("tutorial & example");
 }
 catch (NullPointerException ne)
 {
 System.out.println("Inside the Java catch block " + ne);
 }
 finally
 {
 System.out.println("Inside the Java finally block.");
    // try-catch block inside the finally block
    try
    {
        // raising the ArithmeticException
        // inside the finally block
        int x = 78 / 0;
    }
 catch(ArithmeticException ae)
    {
 System.out.println("Handling exception successfully in the catch block. " + ae);
    }
 }
 // the last print statement
 System.out.println("Finally, out of the try - catch - finally block.");
 }  
 } 
```

**输出:**

```
 Inside the Java try block.
 Inside the Java catch block java.lang.NullPointerException
 Inside the Java finally block.
 Handling exception successfully in the catch block. java.lang.ArithmeticException: / by zero
 Finally, out of the try - catch - finally block. 
```

**解释:**上面的程序显示了一个异常可以在*最终*块中被引发和处理。