# Java 尝试捕捉块

> 原文：<https://www.tutorialandexample.com/java-try-catch-block>

### Java Try 块

代码块中异常的处理是借助 java try 块完成的。它抛出包含在块中的代码，这意味着抛出异常。这个 try 块必须并且应该只在方法中使用。

 **当剩余的代码块没有被执行时，try 块中的特定语句或代码已经被排除。因此，要记住代码不应该保存在 try 块中，这样它就不再是一个异常。

**Java 语言中 try-catch 的语法**

```
try {    
//block of program that handles the exception
}catch (class_Name_ofException ref) {} 
```

**Java 语言中 try-finally 块的语法**

```
try {    
//block of program handles the exception
} finally block {} 
```

### Java Catch 块

java 编程语言中 catch 块异常的处理是通过根据给定的参数验证异常的类型来完成的。已经验证或初始化的异常必须是父类异常或生成的异常类型。总之，声明生成的异常类型是一个好方法。

**Java try-catch:内部工作**

1.  首先，java 虚拟机将验证或检查给定的异常是否被处理。
2.  **如果异常没有被处理，JVM 给出一个缺省值或缺省异常。**
3.  ****它还提供了默认的异常处理程序，用于以下任务:****
4.  ******重新打印异常描述。******
5.  ******执行堆栈跟踪(异常发生的层次方法)******
6.  ******帮助终止程序******

 ******在异常之后，可能会出现许多行代码，可能有 100 行或更多。如果代码没有被处理，异常下面的每个代码都不能被执行。

**例 1**

```
CatchEx1.java
public class CatchEx1 {  

    public static void main (String [] s) {  
        try  
        {  
        int i=80/0.
        }  
catch (e)  
        {  
            System.out.println(e).
        }  
        System.out.println("remaining of the code prints");
    }  

} 
```

**输出:**

```
remaining of the code prints
```

如以上程序所解释和显示的，执行程序的剩余部分，即打印代码语句的剩余部分。

**例 2**

程序已在不会引发异常的块中返回。

```
CatchEx2.java
public class CatchEx2{  
    public static void main (String [] args) {  
        try  
        {  
        int d=110/0.
        System.out.println("remaining of the code");  
        }  
catch (ArithmeticException e)  
        {  
            System.out.println(e);  
        }  
    }  
      }
```

**输出:**

```
/ by zero

```

 **给定代码或程序的 try 块中发生异常，此时块代码的其余部分将不被打印或运行。

**例 3**

在这个例子中，我们将使用父类异常来处理异常。

```
CatchEx3.java
public class CatchEx3 {  

    public static void main (String [] s) {  
        try  
        {  
        int A=150/0.
catch (Exception e)  
        {  
            System.out.println(e);  
        }  
        System.out.println("remaining of the program is printed").
    }  

} 
```

**输出:**

```
remaining of the program is printed
```

**例 4**

这里我们有一个修改 catch 块中异常的例子。

```
CatchEx4.java
public class CatchEx4 {  

    public static void main (String [] s) {  
        int k=400;  
        int l=0;  
        int data;  
        try  
        {  
        data=k/l.
        }    
catch (Exception e)  
        {  
             // the exception in catch blockis modifying or resolving
            System.out.println(k/l+2)).
        }  
    }  
} 
```

**输出:**

```
200
```

**例 5**

在这个例子中，考虑到 try 块，我们还在 catch 块中显示了异常代码。

```
CatchEx5.java
public class CatchEx5 {    
    public static void main (String [] s) {  
        try  
        {  
        int A1=500/0.
        }  
             // exception is handled
catch (Exception e)  
        {  
            // generating the exception in catch block  
        int A2=500/0; //may throw exception   

        }  
    System.out.println("remaining of the code");  
    }  
} 
```

在本例中，异常代码没有写入 catch 块。因此，try 块和 catch 块中的代码只能处理该程序的异常。

**例 6**

我们用各种类型的异常类(ArrayIndexOutOfBoundsException-AIOOBException)来维护给定的异常(算术异常)。

```
CatchEx6.java
public class CatchEx6 { 
    public static void main (String [] args) {  
        try  
        {  
int B=50/0.
        }  
catch (AIOOBException e)  
        {  
            System.out.println(e);  
        }  
        System.out.println("remaining of the code");  
    }  

} 
```

**例 7**

一个处理检查异常的例子。

```
TryCatchEx7.java
import java.io. FileNotFoundException.
import java.io. PrintWriter.

public class TryCatchEx7{  

    public static void main (String [] args) {   
pw.
        try {  
            pw = new PrintWriter("jtp.txt").
pw. println("saved").
        }  
// checked exception handler by providing handling access
 catch (FileNotFoundException e) {  

            System.out.println(e).
        }         
    System.out.println("successfully file is saved").
    }  
} 
```

**输出:**

```
Successfully file is saved
```**********